Workbook

Sheet ReturnData
A1: Date | B1: Food | C1: Mines | D1: Oil | E1: Clths | F1: Durbl | G1: Chems | H1: Cnsum | I1: Cnstr | J1: Steel | K1: FabPr | L1: Machn | M1: Cars | N1: Trans | O1: Utils | P1: Rtail | Q1: Finan
A2: 197401 | B2: 0.0155 | C2: 0.05 | D2: -0.085 | E2: 0.1032 | F2: -0.018 | G2: 0.0191 | H2: -0.0177 | I2: 0.0623 | J2: 0.049 | K2: -0.0059 | L2: -0.0038 | M2: 0.1175 | N2: 0.0296 | O2: 0.0455 | P2: 0.0675 | Q2: 0.003
A3: 197402 | B3: 0.0013 | C3: 0.0214 | D3: -0.0135 | E3: 0.0129 | F3: -0.0329 | G3: 0.0193 | H3: -0.0136 | I3: 0.0383 | J3: 0.0344 | K3: -0.0031 | L3: -0.0061 | M3: -0.0034 | N3: 0.0695 | O3: 0.0029 | P3: 0.0065 | Q3: 0.0059
A4: 197403 | B4: -0.0238 | C4: -0.0457 | D4: -0.0355 | E4: 0.0064 | F4: -0.0047 | G4: 0.0156 | H4: 0.002 | I4: -0.0066 | J4: -0.0266 | K4: -0.0342 | L4: -0.0283 | M4: 0.0027 | N4: -0.0502 | O4: -0.0364 | P4: -0.0364 | Q4: -0.0412
A5: 197404 | B5: -0.0338 | C5: -0.0716 | D5: -0.0678 | E5: -0.0261 | F5: -0.0552 | G5: 0.0099 | H5: -0.0148 | I5: -0.0444 | J5: 0.0018 | K5: -0.0607 | L5: -0.0339 | M5: -0.0279 | N5: -0.0352 | O5: -0.1219 | P5: -0.0187 | Q5: -0.0684
A6: 197405 | B6: -0.0394 | C6: -0.0784 | D6: -0.0756 | E6: -0.0692 | F6: 0.0018 | G6: -0.0011 | H6: 0.0104 | I6: -0.0675 | J6: -0.0887 | K6: -0.1141 | L6: -0.0463 | M6: 0.0283 | N6: -0.0514 | O6: -0.049 | P6: 0.0189 | Q6: -0.1008
A7: 197406 | B7: -0.0046 | C7: 0.0077 | D7: 0.0008 | E7: -0.0256 | F7: -0.0182 | G7: 0.005 | H7: -0.0051 | I7: -0.0468 | J7: 0.03 | K7: -0.0207 | L7: -0.0263 | M7: -0.0338 | N7: -0.0115 | O7: -0.0618 | P7: -0.0255 | Q7: -0.0681
A8: 197407 | B8: -0.1219 | C8: 0.0494 | D8: -0.0083 | E8: -0.033 | F8: -0.1377 | G8: -0.0437 | H8: -0.1287 | I8: -0.0547 | J8: 0.0398 | K8: -0.07 | L8: -0.0778 | M8: -0.1201 | N8: -0.0653 | O8: 0.0077 | P8: -0.1376 | Q8: -0.0723
A9: 197408 | B9: -0.1218 | C9: -0.0914 | D9: -0.0851 | E9: -0.0618 | F9: -0.1057 | G9: -0.1113 | H9: -0.0817 | I9: -0.0946 | J9: -0.0799 | K9: -0.0814 | L9: -0.0679 | M9: -0.0396 | N9: -0.0938 | O9: -0.0862 | P9: -0.1358 | Q9: -0.1176
A10: 197409 | B10: -0.1346 | C10: -0.1234 | D10: -0.0799 | E10: -0.097 | F10: -0.1826 | G10: -0.1022 | H10: -0.1505 | I10: -0.1067 | J10: -0.0814 | K10: -0.092 | L10: -0.1596 | M10: -0.0994 | N10: -0.0872 | O10: -0.0131 | P10: -0.1257 | Q10: -0.0712
A11: 197410 | B11: 0.1888 | C11: 0.2227 | D11: 0.215 | E11: 0.0476 | F11: 0.1323 | G11: 0.1794 | H11: 0.2897 | I11: 0.1458 | J11: 0.0981 | K11: 0.1491 | L11: 0.1772 | M11: -0.0301 | N11: 0.1563 | O11: 0.1301 | P11: 0.0895 | Q11: 0.2103
A12: 197411 | B12: -0.035 | C12: -0.0168 | D12: -0.0415 | E12: -0.1281 | F12: -0.0726 | G12: -0.1008 | H12: -0.002 | I12: -0.0553 | J12: -0.014 | K12: 0.0028 | L12: -0.0475 | M12: -0.0629 | N12: -0.051 | O12: -0.0013 | P12: -0.0598 | Q12: -0.0212
A13: 197412 | B13: -0.0039 | C13: -0.0595 | D13: 0.012 | E13: -0.0271 | F13: -0.0756 | G13: -0.0378 | H13: -0.0228 | I13: -0.054 | J13: -0.0383 | K13: -0.0034 | L13: -0.0507 | M13: 0.0033 | N13: -0.0601 | O13: -0.0081 | P13: -0.0342 | Q13: -0.0267
... A613: 202412 | B613: -0.048 | C613: -0.1198 | D613: -0.0874 | E613: 0.0139 | F613: -0.0566 | G613: -0.1104 | H613: -0.0541 | I613: -0.1218 | J613: -0.1799 | K613: -0.0903 | L613: -0.0019 | M613: 0.0981 | N613: -0.0665 | O613: -0.0778 | P613: 0.006 | Q613: -0.0733

Sheet Momentum Signal
A1: Date | B1: Food | C1: Mines | D1: Oil | E1: Clths | F1: Durbl | G1: Chems | H1: Cnsum | I1: Cnstr | J1: Steel | K1: FabPr | L1: Machn | M1: Cars | N1: Trans | O1: Utils | P1: Rtail | Q1: Finan
A2: =ReturnData!A14 -> 197501 | B2: =AVERAGE(ReturnData!B2:B12) -> -0.028118182 | C2: =AVERAGE(ReturnData!C2:C12) -> -0.0069181818 | D2: =AVERAGE(ReturnData!D2:D12) -> -0.025127273 | E2: =AVERAGE(ReturnData!E2:E12) -> -0.024609091 | F2: =AVERAGE(ReturnData!F2:F12) -> -0.044863636 | G2: =AVERAGE(ReturnData!G2:G12) -> -0.010072727 | H2: =AVERAGE(ReturnData!H2:H12) -> -0.010181818 | I2: =AVERAGE(ReturnData!I2:I12) -> -0.020927273 | ... Q2: =AVERAGE(ReturnData!Q2:Q12) -> -0.031054545
A3: =ReturnData!A15 -> 197502 | B3: =AVERAGE(ReturnData!B3:B13) -> -0.029881818 | C3: =AVERAGE(ReturnData!C3:C13) -> -0.016872727 | D3: =AVERAGE(ReturnData!D3:D13) -> -0.016309091 | E3: =AVERAGE(ReturnData!E3:E13) -> -0.036454545 | F3: =AVERAGE(ReturnData!F3:F13) -> -0.0501 | G3: =AVERAGE(ReturnData!G3:G13) -> -0.015245455 | H3: =AVERAGE(ReturnData!H3:H13) -> -0.010645455 | I3: =AVERAGE(ReturnData!I3:I13) -> -0.0315 | ... Q3: =AVERAGE(ReturnData!Q3:Q13) -> -0.033754545
A4: =ReturnData!A16 -> 197503 | B4: =AVERAGE(ReturnData!B4:B14) -> -0.011727273 | C4: =AVERAGE(ReturnData!C4:C14) -> -0.0080727273 | D4: =AVERAGE(ReturnData!D4:D14) -> -0.010645455 | E4: =AVERAGE(ReturnData!E4:E14) -> -0.013827273 | F4: =AVERAGE(ReturnData!F4:F14) -> -0.028690909 | G4: =AVERAGE(ReturnData!G4:G14) -> -0.0077181818 | H4: =AVERAGE(ReturnData!H4:H14) -> -0.0072818182 | I4: =AVERAGE(ReturnData!I4:I14) -> -0.011254545 | ... Q4: =AVERAGE(ReturnData!Q4:Q14) -> -0.018590909
A5: =ReturnData!A17 -> 197504 | B5: =AVERAGE(ReturnData!B5:B15) -> -0.0046181818 | C5: =AVERAGE(ReturnData!C5:C15) -> 0.0012909091 | D5: =AVERAGE(ReturnData!D5:D15) -> -0.0052272727 | E5: =AVERAGE(ReturnData!E5:E15) -> -0.012927273 | F5: =AVERAGE(ReturnData!F5:F15) -> -0.016309091 | G5: =AVERAGE(ReturnData!G5:G15) -> -0.00085454545 | H5: =AVERAGE(ReturnData!H5:H15) -> 0.0027818182 | I5: =AVERAGE(ReturnData!I5:I15) -> -0.0076090909 | ... Q5: =AVERAGE(ReturnData!Q5:Q15) -> -0.0146
A6: =ReturnData!A18 -> 197505 | B6: =AVERAGE(ReturnData!B6:B16) -> 0.0035090909 | C6: =AVERAGE(ReturnData!C6:C16) -> 0.016036364 | D6: =AVERAGE(ReturnData!D6:D16) -> -0.0010090909 | E6: =AVERAGE(ReturnData!E6:E16) -> 0.0036272727 | F6: =AVERAGE(ReturnData!F6:F16) -> -0.0068636364 | G6: =AVERAGE(ReturnData!G6:G16) -> 0.0037 | H6: =AVERAGE(ReturnData!H6:H16) -> 0.0061 | I6: =AVERAGE(ReturnData!I6:I16) -> 0.0041090909 | ... Q6: =AVERAGE(ReturnData!Q6:Q16) -> -0.0061
A7: =ReturnData!A19 -> 197506 | B7: =AVERAGE(ReturnData!B7:B17) -> 0.008 | C7: =AVERAGE(ReturnData!C7:C17) -> 0.032427273 | D7: =AVERAGE(ReturnData!D7:D17) -> 0.0126 | E7: =AVERAGE(ReturnData!E7:E17) -> 0.016545455 | F7: =AVERAGE(ReturnData!F7:F17) -> 0.00069090909 | G7: =AVERAGE(ReturnData!G7:G17) -> 0.018590909 | H7: =AVERAGE(ReturnData!H7:H17) -> 0.0064454545 | I7: =AVERAGE(ReturnData!I7:I17) -> 0.013290909 | ... Q7: =AVERAGE(ReturnData!Q7:Q17) -> 0.0042909091
A8: =ReturnData!A20 -> 197507 | B8: =AVERAGE(ReturnData!B8:B18) -> 0.014309091 | C8: =AVERAGE(ReturnData!C8:C18) -> 0.038854545 | D8: =AVERAGE(ReturnData!D8:D18) -> 0.023936364 | E8: =AVERAGE(ReturnData!E8:E18) -> 0.021618182 | F8: =AVERAGE(ReturnData!F8:F18) -> 0.0030181818 | G8: =AVERAGE(ReturnData!G8:G18) -> 0.018372727 | H8: =AVERAGE(ReturnData!H8:H18) -> 0.012509091 | I8: =AVERAGE(ReturnData!I8:I18) -> 0.022418182 | ... Q8: =AVERAGE(ReturnData!Q8:Q18) -> 0.016309091
A9: =ReturnData!A21 -> 197508 | B9: =AVERAGE(ReturnData!B9:B19) -> 0.029818182 | C9: =AVERAGE(ReturnData!C9:C19) -> 0.038281818 | D9: =AVERAGE(ReturnData!D9:D19) -> 0.0308 | E9: =AVERAGE(ReturnData!E9:E19) -> 0.032436364 | F9: =AVERAGE(ReturnData!F9:F19) -> 0.019018182 | G9: =AVERAGE(ReturnData!G9:G19) -> 0.026272727 | H9: =AVERAGE(ReturnData!H9:H19) -> 0.025481818 | I9: =AVERAGE(ReturnData!I9:I19) -> 0.032445455 | ... Q9: =AVERAGE(ReturnData!Q9:Q19) -> 0.028654545
A10: =ReturnData!A22 -> 197509 | B10: =AVERAGE(ReturnData!B10:B20) -> 0.036045455 | C10: =AVERAGE(ReturnData!C10:C20) -> 0.043090909 | D10: =AVERAGE(ReturnData!D10:D20) -> 0.034563636 | E10: =AVERAGE(ReturnData!E10:E20) -> 0.034836364 | F10: =AVERAGE(ReturnData!F10:F20) -> 0.021509091 | G10: =AVERAGE(ReturnData!G10:G20) -> 0.032281818 | H10: =AVERAGE(ReturnData!H10:H20) -> 0.023136364 | I10: =AVERAGE(ReturnData!I10:I20) -> 0.035827273 | ... Q10: =AVERAGE(ReturnData!Q10:Q20) -> 0.032690909
A11: =ReturnData!A23 -> 197510 | B11: =AVERAGE(ReturnData!B11:B21) -> 0.046118182 | C11: =AVERAGE(ReturnData!C11:C21) -> 0.0477 | D11: =AVERAGE(ReturnData!D11:D21) -> 0.041309091 | E11: =AVERAGE(ReturnData!E11:E21) -> 0.039781818 | F11: =AVERAGE(ReturnData!F11:F21) -> 0.034881818 | G11: =AVERAGE(ReturnData!G11:G21) -> 0.043372727 | H11: =AVERAGE(ReturnData!H11:H21) -> 0.033018182 | I11: =AVERAGE(ReturnData!I11:I21) -> 0.044263636 | ... Q11: =AVERAGE(ReturnData!Q11:Q21) -> 0.033581818
A12: =ReturnData!A24 -> 197511 | B12: =AVERAGE(ReturnData!B12:B22) -> 0.026063636 | C12: =AVERAGE(ReturnData!C12:C22) -> 0.025018182 | D12: =AVERAGE(ReturnData!D12:D22) -> 0.020790909 | E12: =AVERAGE(ReturnData!E12:E22) -> 0.036072727 | F12: =AVERAGE(ReturnData!F12:F22) -> 0.019072727 | G12: =AVERAGE(ReturnData!G12:G22) -> 0.019345455 | H12: =AVERAGE(ReturnData!H12:H22) -> 0.0023272727 | I12: =AVERAGE(ReturnData!I12:I22) -> 0.025063636 | ... Q12: =AVERAGE(ReturnData!Q12:Q22) -> 0.0076363636
A13: =ReturnData!A25 -> 197512 | B13: =AVERAGE(ReturnData!B13:B23) -> 0.039945455 | C13: =AVERAGE(ReturnData!C13:C23) -> 0.021990909 | D13: =AVERAGE(ReturnData!D13:D23) -> 0.023227273 | E13: =AVERAGE(ReturnData!E13:E23) -> 0.057372727 | F13: =AVERAGE(ReturnData!F13:F23) -> 0.033654545 | G13: =AVERAGE(ReturnData!G13:G23) -> 0.034718182 | H13: =AVERAGE(ReturnData!H13:H23) -> 0.011345455 | I13: =AVERAGE(ReturnData!I13:I23) -> 0.033872727 | ... Q13: =AVERAGE(ReturnData!Q13:Q23) -> 0.014136364
... A601: =ReturnData!A613 -> 202412 | B601: =AVERAGE(ReturnData!B601:B611) -> 0.0067454545 | C601: =AVERAGE(ReturnData!C601:C611) -> 0.025136364 | D601: =AVERAGE(ReturnData!D601:D611) -> 0.0048090909 | E601: =AVERAGE(ReturnData!E601:E611) -> -0.0093 | F601: =AVERAGE(ReturnData!F601:F611) -> 0.0087454545 | G601: =AVERAGE(ReturnData!G601:G611) -> 0.010572727 | H601: =AVERAGE(ReturnData!H601:H611) -> 0.015981818 | I601: =AVERAGE(ReturnData!I601:I611) -> 0.028736364 | ... Q601: =AVERAGE(ReturnData!Q601:Q611) -> 0.0249

Sheet Monthly Ranks
A1: Date | B1: Food | C1: Mines | D1: Oil | E1: Clths | F1: Durbl | G1: Chems | H1: Cnsum | I1: Cnstr | J1: Steel | K1: FabPr | L1: Machn | M1: Cars | N1: Trans | O1: Utils | P1: Rtail | Q1: Finan
A2: ='Momentum Signal'!A2 -> 197501 | B2: =RANK('Momentum Signal'!B2,'Momentum Signal'!$B2:$Q2) -> 11 | C2: =RANK('Momentum Signal'!C2,'Momentum Signal'!$B2:$Q2) -> 2 | D2: =RANK('Momentum Signal'!D2,'Momentum Signal'!$B2:$Q2) -> 10 | E2: =RANK('Momentum Signal'!E2,'Momentum Signal'!$B2:$Q2) -> 9 | F2: =RANK('Momentum Signal'!F2,'Momentum Signal'!$B2:$Q2) -> 16 | G2: =RANK('Momentum Signal'!G2,'Momentum Signal'!$B2:$Q2) -> 3 | H2: =RANK('Momentum Signal'!H2,'Momentum Signal'!$B2:$Q2) -> 4 | I2: =RANK('Momentum Signal'!I2,'Momentum Signal'!$B2:$Q2) -> 7 | ... Q2: =RANK('Momentum Signal'!Q2,'Momentum Signal'!$B2:$Q2) -> 14
A3: ='Momentum Signal'!A3 -> 197502 | B3: =RANK('Momentum Signal'!B3,'Momentum Signal'!$B3:$Q3) -> 9 | C3: =RANK('Momentum Signal'!C3,'Momentum Signal'!$B3:$Q3) -> 5 | D3: =RANK('Momentum Signal'!D3,'Momentum Signal'!$B3:$Q3) -> 4 | E3: =RANK('Momentum Signal'!E3,'Momentum Signal'!$B3:$Q3) -> 14 | F3: =RANK('Momentum Signal'!F3,'Momentum Signal'!$B3:$Q3) -> 16 | G3: =RANK('Momentum Signal'!G3,'Momentum Signal'!$B3:$Q3) -> 3 | H3: =RANK('Momentum Signal'!H3,'Momentum Signal'!$B3:$Q3) -> 1 | I3: =RANK('Momentum Signal'!I3,'Momentum Signal'!$B3:$Q3) -> 10 | ... Q3: =RANK('Momentum Signal'!Q3,'Momentum Signal'!$B3:$Q3) -> 12
A4: ='Momentum Signal'!A4 -> 197503 | B4: =RANK('Momentum Signal'!B4,'Momentum Signal'!$B4:$Q4) -> 8 | C4: =RANK('Momentum Signal'!C4,'Momentum Signal'!$B4:$Q4) -> 5 | D4: =RANK('Momentum Signal'!D4,'Momentum Signal'!$B4:$Q4) -> 6 | E4: =RANK('Momentum Signal'!E4,'Momentum Signal'!$B4:$Q4) -> 10 | F4: =RANK('Momentum Signal'!F4,'Momentum Signal'!$B4:$Q4) -> 16 | G4: =RANK('Momentum Signal'!G4,'Momentum Signal'!$B4:$Q4) -> 4 | H4: =RANK('Momentum Signal'!H4,'Momentum Signal'!$B4:$Q4) -> 3 | I4: =RANK('Momentum Signal'!I4,'Momentum Signal'!$B4:$Q4) -> 7 | ... Q4: =RANK('Momentum Signal'!Q4,'Momentum Signal'!$B4:$Q4) -> 14
A5: ='Momentum Signal'!A5 -> 197504 | B5: =RANK('Momentum Signal'!B5,'Momentum Signal'!$B5:$Q5) -> 6 | C5: =RANK('Momentum Signal'!C5,'Momentum Signal'!$B5:$Q5) -> 3 | D5: =RANK('Momentum Signal'!D5,'Momentum Signal'!$B5:$Q5) -> 7 | E5: =RANK('Momentum Signal'!E5,'Momentum Signal'!$B5:$Q5) -> 13 | F5: =RANK('Momentum Signal'!F5,'Momentum Signal'!$B5:$Q5) -> 16 | G5: =RANK('Momentum Signal'!G5,'Momentum Signal'!$B5:$Q5) -> 5 | H5: =RANK('Momentum Signal'!H5,'Momentum Signal'!$B5:$Q5) -> 2 | I5: =RANK('Momentum Signal'!I5,'Momentum Signal'!$B5:$Q5) -> 11 | ... Q5: =RANK('Momentum Signal'!Q5,'Momentum Signal'!$B5:$Q5) -> 15
A6: ='Momentum Signal'!A6 -> 197505 | B6: =RANK('Momentum Signal'!B6,'Momentum Signal'!$B6:$Q6) -> 8 | C6: =RANK('Momentum Signal'!C6,'Momentum Signal'!$B6:$Q6) -> 1 | D6: =RANK('Momentum Signal'!D6,'Momentum Signal'!$B6:$Q6) -> 12 | E6: =RANK('Momentum Signal'!E6,'Momentum Signal'!$B6:$Q6) -> 7 | F6: =RANK('Momentum Signal'!F6,'Momentum Signal'!$B6:$Q6) -> 16 | G6: =RANK('Momentum Signal'!G6,'Momentum Signal'!$B6:$Q6) -> 6 | H6: =RANK('Momentum Signal'!H6,'Momentum Signal'!$B6:$Q6) -> 4 | I6: =RANK('Momentum Signal'!I6,'Momentum Signal'!$B6:$Q6) -> 5 | ... Q6: =RANK('Momentum Signal'!Q6,'Momentum Signal'!$B6:$Q6) -> 15
A7: ='Momentum Signal'!A7 -> 197506 | B7: =RANK('Momentum Signal'!B7,'Momentum Signal'!$B7:$Q7) -> 10 | C7: =RANK('Momentum Signal'!C7,'Momentum Signal'!$B7:$Q7) -> 2 | D7: =RANK('Momentum Signal'!D7,'Momentum Signal'!$B7:$Q7) -> 8 | E7: =RANK('Momentum Signal'!E7,'Momentum Signal'!$B7:$Q7) -> 4 | F7: =RANK('Momentum Signal'!F7,'Momentum Signal'!$B7:$Q7) -> 15 | G7: =RANK('Momentum Signal'!G7,'Momentum Signal'!$B7:$Q7) -> 3 | H7: =RANK('Momentum Signal'!H7,'Momentum Signal'!$B7:$Q7) -> 12 | I7: =RANK('Momentum Signal'!I7,'Momentum Signal'!$B7:$Q7) -> 5 | ... Q7: =RANK('Momentum Signal'!Q7,'Momentum Signal'!$B7:$Q7) -> 13
A8: ='Momentum Signal'!A8 -> 197507 | B8: =RANK('Momentum Signal'!B8,'Momentum Signal'!$B8:$Q8) -> 12 | C8: =RANK('Momentum Signal'!C8,'Momentum Signal'!$B8:$Q8) -> 1 | D8: =RANK('Momentum Signal'!D8,'Momentum Signal'!$B8:$Q8) -> 4 | E8: =RANK('Momentum Signal'!E8,'Momentum Signal'!$B8:$Q8) -> 6 | F8: =RANK('Momentum Signal'!F8,'Momentum Signal'!$B8:$Q8) -> 16 | G8: =RANK('Momentum Signal'!G8,'Momentum Signal'!$B8:$Q8) -> 7 | H8: =RANK('Momentum Signal'!H8,'Momentum Signal'!$B8:$Q8) -> 13 | I8: =RANK('Momentum Signal'!I8,'Momentum Signal'!$B8:$Q8) -> 5 | ... Q8: =RANK('Momentum Signal'!Q8,'Momentum Signal'!$B8:$Q8) -> 10
A9: ='Momentum Signal'!A9 -> 197508 | B9: =RANK('Momentum Signal'!B9,'Momentum Signal'!$B9:$Q9) -> 7 | C9: =RANK('Momentum Signal'!C9,'Momentum Signal'!$B9:$Q9) -> 1 | D9: =RANK('Momentum Signal'!D9,'Momentum Signal'!$B9:$Q9) -> 6 | E9: =RANK('Momentum Signal'!E9,'Momentum Signal'!$B9:$Q9) -> 4 | F9: =RANK('Momentum Signal'!F9,'Momentum Signal'!$B9:$Q9) -> 16 | G9: =RANK('Momentum Signal'!G9,'Momentum Signal'!$B9:$Q9) -> 12 | H9: =RANK('Momentum Signal'!H9,'Momentum Signal'!$B9:$Q9) -> 13 | I9: =RANK('Momentum Signal'!I9,'Momentum Signal'!$B9:$Q9) -> 3 | ... Q9: =RANK('Momentum Signal'!Q9,'Momentum Signal'!$B9:$Q9) -> 8
A10: ='Momentum Signal'!A10 -> 197509 | B10: =RANK('Momentum Signal'!B10,'Momentum Signal'!$B10:$Q10) -> 4 | C10: =RANK('Momentum Signal'!C10,'Momentum Signal'!$B10:$Q10) -> 1 | D10: =RANK('Momentum Signal'!D10,'Momentum Signal'!$B10:$Q10) -> 7 | E10: =RANK('Momentum Signal'!E10,'Momentum Signal'!$B10:$Q10) -> 6 | F10: =RANK('Momentum Signal'!F10,'Momentum Signal'!$B10:$Q10) -> 16 | G10: =RANK('Momentum Signal'!G10,'Momentum Signal'!$B10:$Q10) -> 11 | H10: =RANK('Momentum Signal'!H10,'Momentum Signal'!$B10:$Q10) -> 14 | I10: =RANK('Momentum Signal'!I10,'Momentum Signal'!$B10:$Q10) -> 5 | ... Q10: =RANK('Momentum Signal'!Q10,'Momentum Signal'!$B10:$Q10) -> 10
A11: ='Momentum Signal'!A11 -> 197510 | B11: =RANK('Momentum Signal'!B11,'Momentum Signal'!$B11:$Q11) -> 2 | C11: =RANK('Momentum Signal'!C11,'Momentum Signal'!$B11:$Q11) -> 1 | D11: =RANK('Momentum Signal'!D11,'Momentum Signal'!$B11:$Q11) -> 7 | E11: =RANK('Momentum Signal'!E11,'Momentum Signal'!$B11:$Q11) -> 8 | F11: =RANK('Momentum Signal'!F11,'Momentum Signal'!$B11:$Q11) -> 14 | G11: =RANK('Momentum Signal'!G11,'Momentum Signal'!$B11:$Q11) -> 5 | H11: =RANK('Momentum Signal'!H11,'Momentum Signal'!$B11:$Q11) -> 16 | I11: =RANK('Momentum Signal'!I11,'Momentum Signal'!$B11:$Q11) -> 4 | ... Q11: =RANK('Momentum Signal'!Q11,'Momentum Signal'!$B11:$Q11) -> 15
A12: ='Momentum Signal'!A12 -> 197511 | B12: =RANK('Momentum Signal'!B12,'Momentum Signal'!$B12:$Q12) -> 4 | C12: =RANK('Momentum Signal'!C12,'Momentum Signal'!$B12:$Q12) -> 9 | D12: =RANK('Momentum Signal'!D12,'Momentum Signal'!$B12:$Q12) -> 10 | E12: =RANK('Momentum Signal'!E12,'Momentum Signal'!$B12:$Q12) -> 2 | F12: =RANK('Momentum Signal'!F12,'Momentum Signal'!$B12:$Q12) -> 13 | G12: =RANK('Momentum Signal'!G12,'Momentum Signal'!$B12:$Q12) -> 12 | H12: =RANK('Momentum Signal'!H12,'Momentum Signal'!$B12:$Q12) -> 16 | I12: =RANK('Momentum Signal'!I12,'Momentum Signal'!$B12:$Q12) -> 8 | ... Q12: =RANK('Momentum Signal'!Q12,'Momentum Signal'!$B12:$Q12) -> 15
A13: ='Momentum Signal'!A13 -> 197512 | B13: =RANK('Momentum Signal'!B13,'Momentum Signal'!$B13:$Q13) -> 4 | C13: =RANK('Momentum Signal'!C13,'Momentum Signal'!$B13:$Q13) -> 14 | D13: =RANK('Momentum Signal'!D13,'Momentum Signal'!$B13:$Q13) -> 13 | E13: =RANK('Momentum Signal'!E13,'Momentum Signal'!$B13:$Q13) -> 1 | F13: =RANK('Momentum Signal'!F13,'Momentum Signal'!$B13:$Q13) -> 7 | G13: =RANK('Momentum Signal'!G13,'Momentum Signal'!$B13:$Q13) -> 5 | H13: =RANK('Momentum Signal'!H13,'Momentum Signal'!$B13:$Q13) -> 16 | I13: =RANK('Momentum Signal'!I13,'Momentum Signal'!$B13:$Q13) -> 6 | ... Q13: =RANK('Momentum Signal'!Q13,'Momentum Signal'!$B13:$Q13) -> 15
... A601: ='Momentum Signal'!A601 -> 202412 | B601: =RANK('Momentum Signal'!B601,'Momentum Signal'!$B601:$Q601) -> 14 | C601: =RANK('Momentum Signal'!C601,'Momentum Signal'!$B601:$Q601) -> 5 | D601: =RANK('Momentum Signal'!D601,'Momentum Signal'!$B601:$Q601) -> 15 | E601: =RANK('Momentum Signal'!E601,'Momentum Signal'!$B601:$Q601) -> 16 | F601: =RANK('Momentum Signal'!F601,'Momentum Signal'!$B601:$Q601) -> 13 | G601: =RANK('Momentum Signal'!G601,'Momentum Signal'!$B601:$Q601) -> 10 | H601: =RANK('Momentum Signal'!H601,'Momentum Signal'!$B601:$Q601) -> 9 | I601: =RANK('Momentum Signal'!I601,'Momentum Signal'!$B601:$Q601) -> 3 | ... Q601: =RANK('Momentum Signal'!Q601,'Momentum Signal'!$B601:$Q601) -> 6

Sheet HighMomentumPortfolio
A1: High Momentum Portfolio Weights | S1: Weights in High Momentum Portfolio * Returns | AK1: Return on High Momentum Portfolio
B2: Food | C2: Mines | D2: Oil | E2: Clths | F2: Durbl | G2: Chems | H2: Cnsum | I2: Cnstr | J2: Steel | K2: FabPr | L2: Machn | M2: Cars | N2: Trans | O2: Utils | P2: Rtail | Q2: Finan | T2: Food | U2: Mines | V2: Oil | W2: Clths | X2: Durbl | Y2: Chems | Z2: Cnsum | AA2: Cnstr | AB2: Steel | AC2: FabPr | AD2: Machn | AE2: Cars | AF2: Trans | AG2: Utils | AH2: Rtail | AI2: Finan | AL2: Return
A3: =ReturnData!A14 -> 197501 | B3: =IF('Monthly Ranks'!B2<=8, 1/8,0) -> 0 | C3: =IF('Monthly Ranks'!C2<=8, 1/8,0) -> 0.125 | D3: =IF('Monthly Ranks'!D2<=8, 1/8,0) -> 0 | E3: =IF('Monthly Ranks'!E2<=8, 1/8,0) -> 0 | F3: =IF('Monthly Ranks'!F2<=8, 1/8,0) -> 0 | G3: =IF('Monthly Ranks'!G2<=8, 1/8,0) -> 0.125 | H3: =IF('Monthly Ranks'!H2<=8, 1/8,0) -> 0.125 | I3: =IF('Monthly Ranks'!I2<=8, 1/8,0) -> 0.125 | ... Q3: =IF('Monthly Ranks'!Q2<=8, 1/8,0) -> 0 | S3: =A3 -> 197501 | T3: =B3*ReturnData!B14 -> 0 | U3: =C3*ReturnData!C14 -> 0.014775 | V3: =D3*ReturnData!D14 -> 0 | W3: =E3*ReturnData!E14 -> 0 | X3: =F3*ReturnData!F14 -> 0 | Y3: =G3*ReturnData!G14 -> 0.0127625 | Z3: =H3*ReturnData!H14 -> 0.002925 | AA3: =I3*ReturnData!I14 -> 0.032625 | ... AI3: =Q3*ReturnData!Q14 -> 0 | AK3: =S3 -> 197501 | AL3: =SUM(T3:AI3) -> 0.1597125
A4: =ReturnData!A15 -> 197502 | B4: =IF('Monthly Ranks'!B3<=8, 1/8,0) -> 0 | C4: =IF('Monthly Ranks'!C3<=8, 1/8,0) -> 0.125 | D4: =IF('Monthly Ranks'!D3<=8, 1/8,0) -> 0.125 | E4: =IF('Monthly Ranks'!E3<=8, 1/8,0) -> 0 | F4: =IF('Monthly Ranks'!F3<=8, 1/8,0) -> 0 | G4: =IF('Monthly Ranks'!G3<=8, 1/8,0) -> 0.125 | H4: =IF('Monthly Ranks'!H3<=8, 1/8,0) -> 0.125 | I4: =IF('Monthly Ranks'!I3<=8, 1/8,0) -> 0 | ... Q4: =IF('Monthly Ranks'!Q3<=8, 1/8,0) -> 0 | S4: =A4 -> 197502 | T4: =B4*ReturnData!B15 -> 0 | U4: =C4*ReturnData!C15 -> 0.0071625 | V4: =D4*ReturnData!D15 -> 0.0030125 | W4: =E4*ReturnData!E15 -> 0 | X4: =F4*ReturnData!F15 -> 0 | Y4: =G4*ReturnData!G15 -> 0.0113875 | Z4: =H4*ReturnData!H15 -> 0.0140875 | AA4: =I4*ReturnData!I15 -> 0 | ... AI4: =Q4*ReturnData!Q15 -> 0 | AK4: =S4 -> 197502 | AL4: =SUM(T4:AI4) -> 0.0532875
A5: =ReturnData!A16 -> 197503 | B5: =IF('Monthly Ranks'!B4<=8, 1/8,0) -> 0.125 | C5: =IF('Monthly Ranks'!C4<=8, 1/8,0) -> 0.125 | D5: =IF('Monthly Ranks'!D4<=8, 1/8,0) -> 0.125 | E5: =IF('Monthly Ranks'!E4<=8, 1/8,0) -> 0 | F5: =IF('Monthly Ranks'!F4<=8, 1/8,0) -> 0 | G5: =IF('Monthly Ranks'!G4<=8, 1/8,0) -> 0.125 | H5: =IF('Monthly Ranks'!H4<=8, 1/8,0) -> 0.125 | I5: =IF('Monthly Ranks'!I4<=8, 1/8,0) -> 0.125 | ... Q5: =IF('Monthly Ranks'!Q4<=8, 1/8,0) -> 0 | S5: =A5 -> 197503 | T5: =B5*ReturnData!B16 -> 0.00695 | U5: =C5*ReturnData!C16 -> 0.011325 | V5: =D5*ReturnData!D16 -> -0.002675 | W5: =E5*ReturnData!E16 -> 0 | X5: =F5*ReturnData!F16 -> 0 | Y5: =G5*ReturnData!G16 -> 0.0075 | Z5: =H5*ReturnData!H16 -> 0.0027125 | AA5: =I5*ReturnData!I16 -> 0.0105625 | ... AI5: =Q5*ReturnData!Q16 -> 0 | AK5: =S5 -> 197503 | AL5: =SUM(T5:AI5) -> 0.0492625
A6: =ReturnData!A17 -> 197504 | B6: =IF('Monthly Ranks'!B5<=8, 1/8,0) -> 0.125 | C6: =IF('Monthly Ranks'!C5<=8, 1/8,0) -> 0.125 | D6: =IF('Monthly Ranks'!D5<=8, 1/8,0) -> 0.125 | E6: =IF('Monthly Ranks'!E5<=8, 1/8,0) -> 0 | F6: =IF('Monthly Ranks'!F5<=8, 1/8,0) -> 0 | G6: =IF('Monthly Ranks'!G5<=8, 1/8,0) -> 0.125 | H6: =IF('Monthly Ranks'!H5<=8, 1/8,0) -> 0.125 | I6: =IF('Monthly Ranks'!I5<=8, 1/8,0) -> 0 | ... Q6: =IF('Monthly Ranks'!Q5<=8, 1/8,0) -> 0 | S6: =A6 -> 197504 | T6: =B6*ReturnData!B17 -> 0.00125 | U6: =C6*ReturnData!C17 -> 0.0127375 | V6: =D6*ReturnData!D17 -> 0.0092625 | W6: =E6*ReturnData!E17 -> 0 | X6: =F6*ReturnData!F17 -> 0 | Y6: =G6*ReturnData!G17 -> 0.0203375 | Z6: =H6*ReturnData!H17 -> 0.001775 | AA6: =I6*ReturnData!I17 -> 0 | ... AI6: =Q6*ReturnData!Q17 -> 0 | AK6: =S6 -> 197504 | AL6: =SUM(T6:AI6) -> 0.0629125
A7: =ReturnData!A18 -> 197505 | B7: =IF('Monthly Ranks'!B6<=8, 1/8,0) -> 0.125 | C7: =IF('Monthly Ranks'!C6<=8, 1/8,0) -> 0.125 | D7: =IF('Monthly Ranks'!D6<=8, 1/8,0) -> 0 | E7: =IF('Monthly Ranks'!E6<=8, 1/8,0) -> 0.125 | F7: =IF('Monthly Ranks'!F6<=8, 1/8,0) -> 0 | G7: =IF('Monthly Ranks'!G6<=8, 1/8,0) -> 0.125 | H7: =IF('Monthly Ranks'!H6<=8, 1/8,0) -> 0.125 | I7: =IF('Monthly Ranks'!I6<=8, 1/8,0) -> 0.125 | ... Q7: =IF('Monthly Ranks'!Q6<=8, 1/8,0) -> 0 | S7: =A7 -> 197505 | T7: =B7*ReturnData!B18 -> 0.0081 | U7: =C7*ReturnData!C18 -> 0.0098 | V7: =D7*ReturnData!D18 -> 0 | W7: =E7*ReturnData!E18 -> 0.003775 | X7: =F7*ReturnData!F18 -> 0 | Y7: =G7*ReturnData!G18 -> 0.000325 | Z7: =H7*ReturnData!H18 -> 0.0077 | AA7: =I7*ReturnData!I18 -> 0.0067 | ... AI7: =Q7*ReturnData!Q18 -> 0 | AK7: =S7 -> 197505 | AL7: =SUM(T7:AI7) -> 0.0406625
A8: =ReturnData!A19 -> 197506 | B8: =IF('Monthly Ranks'!B7<=8, 1/8,0) -> 0 | C8: =IF('Monthly Ranks'!C7<=8, 1/8,0) -> 0.125 | D8: =IF('Monthly Ranks'!D7<=8, 1/8,0) -> 0.125 | E8: =IF('Monthly Ranks'!E7<=8, 1/8,0) -> 0.125 | F8: =IF('Monthly Ranks'!F7<=8, 1/8,0) -> 0 | G8: =IF('Monthly Ranks'!G7<=8, 1/8,0) -> 0.125 | H8: =IF('Monthly Ranks'!H7<=8, 1/8,0) -> 0 | I8: =IF('Monthly Ranks'!I7<=8, 1/8,0) -> 0.125 | ... Q8: =IF('Monthly Ranks'!Q7<=8, 1/8,0) -> 0 | S8: =A8 -> 197506 | T8: =B8*ReturnData!B19 -> 0 | U8: =C8*ReturnData!C19 -> 0.0053875 | V8: =D8*ReturnData!D19 -> 0.0084 | W8: =E8*ReturnData!E19 -> 0.01075 | X8: =F8*ReturnData!F19 -> 0 | Y8: =G8*ReturnData!G19 -> 0.0054 | Z8: =H8*ReturnData!H19 -> 0 | AA8: =I8*ReturnData!I19 -> 0.00695 | ... AI8: =Q8*ReturnData!Q19 -> 0 | AK8: =S8 -> 197506 | AL8: =SUM(T8:AI8) -> 0.062625
A9: =ReturnData!A20 -> 197507 | B9: =IF('Monthly Ranks'!B8<=8, 1/8,0) -> 0 | C9: =IF('Monthly Ranks'!C8<=8, 1/8,0) -> 0.125 | D9: =IF('Monthly Ranks'!D8<=8, 1/8,0) -> 0.125 | E9: =IF('Monthly Ranks'!E8<=8, 1/8,0) -> 0.125 | F9: =IF('Monthly Ranks'!F8<=8, 1/8,0) -> 0 | G9: =IF('Monthly Ranks'!G8<=8, 1/8,0) -> 0.125 | H9: =IF('Monthly Ranks'!H8<=8, 1/8,0) -> 0 | I9: =IF('Monthly Ranks'!I8<=8, 1/8,0) -> 0.125 | ... Q9: =IF('Monthly Ranks'!Q8<=8, 1/8,0) -> 0 | S9: =A9 -> 197507 | T9: =B9*ReturnData!B20 -> 0 | U9: =C9*ReturnData!C20 -> -0.0048125 | V9: =D9*ReturnData!D20 -> -0.0054625 | W9: =E9*ReturnData!E20 -> -0.004425 | X9: =F9*ReturnData!F20 -> 0 | Y9: =G9*ReturnData!G20 -> -0.00565 | Z9: =H9*ReturnData!H20 -> 0 | AA9: =I9*ReturnData!I20 -> -0.007175 | ... AI9: =Q9*ReturnData!Q20 -> 0 | AK9: =S9 -> 197507 | AL9: =SUM(T9:AI9) -> -0.0462625
A10: =ReturnData!A21 -> 197508 | B10: =IF('Monthly Ranks'!B9<=8, 1/8,0) -> 0.125 | C10: =IF('Monthly Ranks'!C9<=8, 1/8,0) -> 0.125 | D10: =IF('Monthly Ranks'!D9<=8, 1/8,0) -> 0.125 | E10: =IF('Monthly Ranks'!E9<=8, 1/8,0) -> 0.125 | F10: =IF('Monthly Ranks'!F9<=8, 1/8,0) -> 0 | G10: =IF('Monthly Ranks'!G9<=8, 1/8,0) -> 0 | H10: =IF('Monthly Ranks'!H9<=8, 1/8,0) -> 0 | I10: =IF('Monthly Ranks'!I9<=8, 1/8,0) -> 0.125 | ... Q10: =IF('Monthly Ranks'!Q9<=8, 1/8,0) -> 0.125 | S10: =A10 -> 197508 | T10: =B10*ReturnData!B21 -> -0.002975 | U10: =C10*ReturnData!C21 -> -0.0090875 | V10: =D10*ReturnData!D21 -> -0.0007125 | W10: =E10*ReturnData!E21 -> -0.005325 | X10: =F10*ReturnData!F21 -> 0 | Y10: =G10*ReturnData!G21 -> 0 | Z10: =H10*ReturnData!H21 -> 0 | AA10: =I10*ReturnData!I21 -> -0.0017375 | ... AI10: =Q10*ReturnData!Q21 -> -0.007675 | AK10: =S10 -> 197508 | AL10: =SUM(T10:AI10) -> -0.0313625
A11: =ReturnData!A22 -> 197509 | B11: =IF('Monthly Ranks'!B10<=8, 1/8,0) -> 0.125 | C11: =IF('Monthly Ranks'!C10<=8, 1/8,0) -> 0.125 | D11: =IF('Monthly Ranks'!D10<=8, 1/8,0) -> 0.125 | E11: =IF('Monthly Ranks'!E10<=8, 1/8,0) -> 0.125 | F11: =IF('Monthly Ranks'!F10<=8, 1/8,0) -> 0 | G11: =IF('Monthly Ranks'!G10<=8, 1/8,0) -> 0 | H11: =IF('Monthly Ranks'!H10<=8, 1/8,0) -> 0 | I11: =IF('Monthly Ranks'!I10<=8, 1/8,0) -> 0.125 | ... Q11: =IF('Monthly Ranks'!Q10<=8, 1/8,0) -> 0 | S11: =A11 -> 197509 | T11: =B11*ReturnData!B22 -> -0.003975 | U11: =C11*ReturnData!C22 -> -0.00335 | V11: =D11*ReturnData!D22 -> -0.0013375 | W11: =E11*ReturnData!E22 -> 0.00085 | X11: =F11*ReturnData!F22 -> 0 | Y11: =G11*ReturnData!G22 -> 0 | Z11: =H11*ReturnData!H22 -> 0 | AA11: =I11*ReturnData!I22 -> -0.008175 | ... AI11: =Q11*ReturnData!Q22 -> 0 | AK11: =S11 -> 197509 | AL11: =SUM(T11:AI11) -> -0.0278625
A12: =ReturnData!A23 -> 197510 | B12: =IF('Monthly Ranks'!B11<=8, 1/8,0) -> 0.125 | C12: =IF('Monthly Ranks'!C11<=8, 1/8,0) -> 0.125 | D12: =IF('Monthly Ranks'!D11<=8, 1/8,0) -> 0.125 | E12: =IF('Monthly Ranks'!E11<=8, 1/8,0) -> 0.125 | F12: =IF('Monthly Ranks'!F11<=8, 1/8,0) -> 0 | G12: =IF('Monthly Ranks'!G11<=8, 1/8,0) -> 0.125 | H12: =IF('Monthly Ranks'!H11<=8, 1/8,0) -> 0 | I12: =IF('Monthly Ranks'!I11<=8, 1/8,0) -> 0.125 | ... Q12: =IF('Monthly Ranks'!Q11<=8, 1/8,0) -> 0 | S12: =A12 -> 197510 | T12: =B12*ReturnData!B23 -> 0.0147125 | U12: =C12*ReturnData!C23 -> -0.0062625 | V12: =D12*ReturnData!D23 -> -0.0018375 | W12: =E12*ReturnData!E23 -> 0.013275 | X12: =F12*ReturnData!F23 -> 0 | Y12: =G12*ReturnData!G23 -> 0.0085375 | Z12: =H12*ReturnData!H23 -> 0 | AA12: =I12*ReturnData!I23 -> 0.0052 | ... AI12: =Q12*ReturnData!Q23 -> 0 | AK12: =S12 -> 197510 | AL12: =SUM(T12:AI12) -> 0.0490625
A13: =ReturnData!A24 -> 197511 | B13: =IF('Monthly Ranks'!B12<=8, 1/8,0) -> 0.125 | C13: =IF('Monthly Ranks'!C12<=8, 1/8,0) -> 0 | D13: =IF('Monthly Ranks'!D12<=8, 1/8,0) -> 0 | E13: =IF('Monthly Ranks'!E12<=8, 1/8,0) -> 0.125 | F13: =IF('Monthly Ranks'!F12<=8, 1/8,0) -> 0 | G13: =IF('Monthly Ranks'!G12<=8, 1/8,0) -> 0 | H13: =IF('Monthly Ranks'!H12<=8, 1/8,0) -> 0 | I13: =IF('Monthly Ranks'!I12<=8, 1/8,0) -> 0.125 | ... Q13: =IF('Monthly Ranks'!Q12<=8, 1/8,0) -> 0 | S13: =A13 -> 197511 | T13: =B13*ReturnData!B24 -> 0.0040125 | U13: =C13*ReturnData!C24 -> 0 | V13: =D13*ReturnData!D24 -> 0 | W13: =E13*ReturnData!E24 -> 0.00835 | X13: =F13*ReturnData!F24 -> 0 | Y13: =G13*ReturnData!G24 -> 0 | Z13: =H13*ReturnData!H24 -> 0 | AA13: =I13*ReturnData!I24 -> 0.0040625 | ... AI13: =Q13*ReturnData!Q24 -> 0 | AK13: =S13 -> 197511 | AL13: =SUM(T13:AI13) -> 0.0340125
A14: =ReturnData!A25 -> 197512 | B14: =IF('Monthly Ranks'!B13<=8, 1/8,0) -> 0.125 | C14: =IF('Monthly Ranks'!C13<=8, 1/8,0) -> 0 | D14: =IF('Monthly Ranks'!D13<=8, 1/8,0) -> 0 | E14: =IF('Monthly Ranks'!E13<=8, 1/8,0) -> 0.125 | F14: =IF('Monthly Ranks'!F13<=8, 1/8,0) -> 0.125 | G14: =IF('Monthly Ranks'!G13<=8, 1/8,0) -> 0.125 | H14: =IF('Monthly Ranks'!H13<=8, 1/8,0) -> 0 | I14: =IF('Monthly Ranks'!I13<=8, 1/8,0) -> 0.125 | ... Q14: =IF('Monthly Ranks'!Q13<=8, 1/8,0) -> 0 | S14: =A14 -> 197512 | T14: =B14*ReturnData!B25 -> -0.0024625 | U14: =C14*ReturnData!C25 -> 0 | V14: =D14*ReturnData!D25 -> 0 | W14: =E14*ReturnData!E25 -> -0.0013125 | X14: =F14*ReturnData!F25 -> -0.00275 | Y14: =G14*ReturnData!G25 -> 2.5e-05 | Z14: =H14*ReturnData!H25 -> 0 | AA14: =I14*ReturnData!I25 -> 0.0009 | ... AI14: =Q14*ReturnData!Q25 -> 0 | AK14: =S14 -> 197512 | AL14: =SUM(T14:AI14) -> -0.006125
... A602: =ReturnData!A613 -> 202412 | B602: =IF('Monthly Ranks'!B601<=8, 1/8,0) -> 0 | C602: =IF('Monthly Ranks'!C601<=8, 1/8,0) -> 0.125 | D602: =IF('Monthly Ranks'!D601<=8, 1/8,0) -> 0 | E602: =IF('Monthly Ranks'!E601<=8, 1/8,0) -> 0 | F602: =IF('Monthly Ranks'!F601<=8, 1/8,0) -> 0 | G602: =IF('Monthly Ranks'!G601<=8, 1/8,0) -> 0 | H602: =IF('Monthly Ranks'!H601<=8, 1/8,0) -> 0 | I602: =IF('Monthly Ranks'!I601<=8, 1/8,0) -> 0.125 | ... Q602: =IF('Monthly Ranks'!Q601<=8, 1/8,0) -> 0.125 | S602: =A602 -> 202412 | T602: =B602*ReturnData!B613 -> 0 | U602: =C602*ReturnData!C613 -> -0.014975 | V602: =D602*ReturnData!D613 -> 0 | W602: =E602*ReturnData!E613 -> 0 | X602: =F602*ReturnData!F613 -> 0 | Y602: =G602*ReturnData!G613 -> 0 | Z602: =H602*ReturnData!H613 -> 0 | AA602: =I602*ReturnData!I613 -> -0.015225 | ... AI602: =Q602*ReturnData!Q613 -> -0.0091625 | AK602: =S602 -> 202412 | AL602: =SUM(T602:AI602) -> -0.068175

Sheet LowMomentumPortfolio
A1: Low Momentum Portfolio Weights | S1: Weights in Low Momentum Portfolio * Returns | AK1: Return on Low Momentum Portfolio
A2: Date | B2: Food | C2: Mines | D2: Oil | E2: Clths | F2: Durbl | G2: Chems | H2: Cnsum | I2: Cnstr | J2: Steel | K2: FabPr | L2: Machn | M2: Cars | N2: Trans | O2: Utils | P2: Rtail | Q2: Finan | S2: =A2 -> Date | T2: Food | U2: Mines | V2: Oil | W2: Clths | X2: Durbl | Y2: Chems | Z2: Cnsum | AA2: Cnstr | AB2: Steel | AC2: FabPr | AD2: Machn | AE2: Cars | AF2: Trans | AG2: Utils | AH2: Rtail | AI2: Finan | AK2: =S2 -> Date | AL2: Return | AO2: LS Portfolio
A3: =ReturnData!A14 -> 197501 | B3: =IF('Monthly Ranks'!B2>=9, 1/8,0) -> 0.125 | C3: =IF('Monthly Ranks'!C2>=9, 1/8,0) -> 0 | D3: =IF('Monthly Ranks'!D2>=9, 1/8,0) -> 0.125 | E3: =IF('Monthly Ranks'!E2>=9, 1/8,0) -> 0.125 | F3: =IF('Monthly Ranks'!F2>=9, 1/8,0) -> 0.125 | G3: =IF('Monthly Ranks'!G2>=9, 1/8,0) -> 0 | H3: =IF('Monthly Ranks'!H2>=9, 1/8,0) -> 0 | I3: =IF('Monthly Ranks'!I2>=9, 1/8,0) -> 0 | ... Q3: =IF('Monthly Ranks'!Q2>=9, 1/8,0) -> 0.125 | S3: =A3 -> 197501 | T3: =B3*ReturnData!B14 -> 0.025125 | U3: =C3*ReturnData!C14 -> 0 | V3: =D3*ReturnData!D14 -> 0.0061 | W3: =E3*ReturnData!E14 -> 0.032725 | X3: =F3*ReturnData!F14 -> 0.025325 | Y3: =G3*ReturnData!G14 -> 0 | Z3: =H3*ReturnData!H14 -> 0 | AA3: =I3*ReturnData!I14 -> 0 | ... AI3: =Q3*ReturnData!Q14 -> 0.0215875 | AK3: =S3 -> 197501 | AL3: =SUM(T3:AI3) -> 0.1807875 | AN3: 1 | AO3: =HighMomentumPortfolio!AL3-LowMomentumPortfolio!AL3 -> -0.021075 | AP3: =AN3+AO3 -> 0.978925 | AR3: =PRODUCT(AP3:AP14) -> 0.99468133 | AU3: Annualized Mean Return | AX3: =AVERAGE(AR3:AR591)-1 -> 0.034549174
A4: =ReturnData!A15 -> 197502 | B4: =IF('Monthly Ranks'!B3>=9, 1/8,0) -> 0.125 | C4: =IF('Monthly Ranks'!C3>=9, 1/8,0) -> 0 | D4: =IF('Monthly Ranks'!D3>=9, 1/8,0) -> 0 | E4: =IF('Monthly Ranks'!E3>=9, 1/8,0) -> 0.125 | F4: =IF('Monthly Ranks'!F3>=9, 1/8,0) -> 0.125 | G4: =IF('Monthly Ranks'!G3>=9, 1/8,0) -> 0 | H4: =IF('Monthly Ranks'!H3>=9, 1/8,0) -> 0 | I4: =IF('Monthly Ranks'!I3>=9, 1/8,0) -> 0.125 | ... Q4: =IF('Monthly Ranks'!Q3>=9, 1/8,0) -> 0.125 | S4: =A4 -> 197502 | T4: =B4*ReturnData!B15 -> 0.0068 | U4: =C4*ReturnData!C15 -> 0 | V4: =D4*ReturnData!D15 -> 0 | W4: =E4*ReturnData!E15 -> 0.0020375 | X4: =F4*ReturnData!F15 -> 0.0164375 | Y4: =G4*ReturnData!G15 -> 0 | Z4: =H4*ReturnData!H15 -> 0 | AA4: =I4*ReturnData!I15 -> 0.0041875 | ... AI4: =Q4*ReturnData!Q15 -> 0.0003375 | AK4: =S4 -> 197502 | AL4: =SUM(T4:AI4) -> 0.0525125 | AN4: 1 | AO4: =HighMomentumPortfolio!AL4-LowMomentumPortfolio!AL4 -> 0.000775 | AP4: =AN4+AO4 -> 1.000775 | AU4: Annualized Std Dev | AX4: =_xlfn.STDEV.P(AO3:AO602)*SQRT(12) -> 0.095015497
A5: =ReturnData!A16 -> 197503 | B5: =IF('Monthly Ranks'!B4>=9, 1/8,0) -> 0 | C5: =IF('Monthly Ranks'!C4>=9, 1/8,0) -> 0 | D5: =IF('Monthly Ranks'!D4>=9, 1/8,0) -> 0 | E5: =IF('Monthly Ranks'!E4>=9, 1/8,0) -> 0.125 | F5: =IF('Monthly Ranks'!F4>=9, 1/8,0) -> 0.125 | G5: =IF('Monthly Ranks'!G4>=9, 1/8,0) -> 0 | H5: =IF('Monthly Ranks'!H4>=9, 1/8,0) -> 0 | I5: =IF('Monthly Ranks'!I4>=9, 1/8,0) -> 0 | ... Q5: =IF('Monthly Ranks'!Q4>=9, 1/8,0) -> 0.125 | S5: =A5 -> 197503 | T5: =B5*ReturnData!B16 -> 0 | U5: =C5*ReturnData!C16 -> 0 | V5: =D5*ReturnData!D16 -> 0 | W5: =E5*ReturnData!E16 -> 0.0195 | X5: =F5*ReturnData!F16 -> 0.0060875 | Y5: =G5*ReturnData!G16 -> 0 | Z5: =H5*ReturnData!H16 -> 0 | AA5: =I5*ReturnData!I16 -> 0 | ... AI5: =Q5*ReturnData!Q16 -> 0.0031375 | AK5: =S5 -> 197503 | AL5: =SUM(T5:AI5) -> 0.0649375 | AN5: 1 | AO5: =HighMomentumPortfolio!AL5-LowMomentumPortfolio!AL5 -> -0.015675 | AP5: =AN5+AO5 -> 0.984325 | AU5: Sharpe Ratio | AX5: =AX3/AX4 -> 0.3636162
A6: =ReturnData!A17 -> 197504 | B6: =IF('Monthly Ranks'!B5>=9, 1/8,0) -> 0 | C6: =IF('Monthly Ranks'!C5>=9, 1/8,0) -> 0 | D6: =IF('Monthly Ranks'!D5>=9, 1/8,0) -> 0 | E6: =IF('Monthly Ranks'!E5>=9, 1/8,0) -> 0.125 | F6: =IF('Monthly Ranks'!F5>=9, 1/8,0) -> 0.125 | G6: =IF('Monthly Ranks'!G5>=9, 1/8,0) -> 0 | H6: =IF('Monthly Ranks'!H5>=9, 1/8,0) -> 0 | I6: =IF('Monthly Ranks'!I5>=9, 1/8,0) -> 0.125 | ... Q6: =IF('Monthly Ranks'!Q5>=9, 1/8,0) -> 0.125 | S6: =A6 -> 197504 | T6: =B6*ReturnData!B17 -> 0 | U6: =C6*ReturnData!C17 -> 0 | V6: =D6*ReturnData!D17 -> 0 | W6: =E6*ReturnData!E17 -> 0.0091125 | X6: =F6*ReturnData!F17 -> 0.0106125 | Y6: =G6*ReturnData!G17 -> 0 | Z6: =H6*ReturnData!H17 -> 0 | AA6: =I6*ReturnData!I17 -> 0.0041875 | ... AI6: =Q6*ReturnData!Q17 -> 0.0016875 | AK6: =S6 -> 197504 | AL6: =SUM(T6:AI6) -> 0.041975 | AN6: 1 | AO6: =HighMomentumPortfolio!AL6-LowMomentumPortfolio!AL6 -> 0.0209375 | AP6: =AN6+AO6 -> 1.0209375
A7: =ReturnData!A18 -> 197505 | B7: =IF('Monthly Ranks'!B6>=9, 1/8,0) -> 0 | C7: =IF('Monthly Ranks'!C6>=9, 1/8,0) -> 0 | D7: =IF('Monthly Ranks'!D6>=9, 1/8,0) -> 0.125 | E7: =IF('Monthly Ranks'!E6>=9, 1/8,0) -> 0 | F7: =IF('Monthly Ranks'!F6>=9, 1/8,0) -> 0.125 | G7: =IF('Monthly Ranks'!G6>=9, 1/8,0) -> 0 | H7: =IF('Monthly Ranks'!H6>=9, 1/8,0) -> 0 | I7: =IF('Monthly Ranks'!I6>=9, 1/8,0) -> 0 | ... Q7: =IF('Monthly Ranks'!Q6>=9, 1/8,0) -> 0.125 | S7: =A7 -> 197505 | T7: =B7*ReturnData!B18 -> 0 | U7: =C7*ReturnData!C18 -> 0 | V7: =D7*ReturnData!D18 -> 0.0156875 | W7: =E7*ReturnData!E18 -> 0 | X7: =F7*ReturnData!F18 -> 0.000925 | Y7: =G7*ReturnData!G18 -> 0 | Z7: =H7*ReturnData!H18 -> 0 | AA7: =I7*ReturnData!I18 -> 0 | ... AI7: =Q7*ReturnData!Q18 -> 0.0080125 | AK7: =S7 -> 197505 | AL7: =SUM(T7:AI7) -> 0.0504 | AN7: 1 | AO7: =HighMomentumPortfolio!AL7-LowMomentumPortfolio!AL7 -> -0.0097375 | AP7: =AN7+AO7 -> 0.9902625
A8: =ReturnData!A19 -> 197506 | B8: =IF('Monthly Ranks'!B7>=9, 1/8,0) -> 0.125 | C8: =IF('Monthly Ranks'!C7>=9, 1/8,0) -> 0 | D8: =IF('Monthly Ranks'!D7>=9, 1/8,0) -> 0 | E8: =IF('Monthly Ranks'!E7>=9, 1/8,0) -> 0 | F8: =IF('Monthly Ranks'!F7>=9, 1/8,0) -> 0.125 | G8: =IF('Monthly Ranks'!G7>=9, 1/8,0) -> 0 | H8: =IF('Monthly Ranks'!H7>=9, 1/8,0) -> 0.125 | I8: =IF('Monthly Ranks'!I7>=9, 1/8,0) -> 0 | ... Q8: =IF('Monthly Ranks'!Q7>=9, 1/8,0) -> 0.125 | S8: =A8 -> 197506 | T8: =B8*ReturnData!B19 -> 0.0060875 | U8: =C8*ReturnData!C19 -> 0 | V8: =D8*ReturnData!D19 -> 0 | W8: =E8*ReturnData!E19 -> 0 | X8: =F8*ReturnData!F19 -> 0.0047875 | Y8: =G8*ReturnData!G19 -> 0 | Z8: =H8*ReturnData!H19 -> 0.00175 | AA8: =I8*ReturnData!I19 -> 0 | ... AI8: =Q8*ReturnData!Q19 -> 0.0079375 | AK8: =S8 -> 197506 | AL8: =SUM(T8:AI8) -> 0.0580875 | AN8: 1 | AO8: =HighMomentumPortfolio!AL8-LowMomentumPortfolio!AL8 -> 0.0045375 | AP8: =AN8+AO8 -> 1.0045375
A9: =ReturnData!A20 -> 197507 | B9: =IF('Monthly Ranks'!B8>=9, 1/8,0) -> 0.125 | C9: =IF('Monthly Ranks'!C8>=9, 1/8,0) -> 0 | D9: =IF('Monthly Ranks'!D8>=9, 1/8,0) -> 0 | E9: =IF('Monthly Ranks'!E8>=9, 1/8,0) -> 0 | F9: =IF('Monthly Ranks'!F8>=9, 1/8,0) -> 0.125 | G9: =IF('Monthly Ranks'!G8>=9, 1/8,0) -> 0 | H9: =IF('Monthly Ranks'!H8>=9, 1/8,0) -> 0.125 | I9: =IF('Monthly Ranks'!I8>=9, 1/8,0) -> 0 | ... Q9: =IF('Monthly Ranks'!Q8>=9, 1/8,0) -> 0.125 | S9: =A9 -> 197507 | T9: =B9*ReturnData!B20 -> -0.0066625 | U9: =C9*ReturnData!C20 -> 0 | V9: =D9*ReturnData!D20 -> 0 | W9: =E9*ReturnData!E20 -> 0 | X9: =F9*ReturnData!F20 -> -0.0097875 | Y9: =G9*ReturnData!G20 -> 0 | Z9: =H9*ReturnData!H20 -> -0.0134375 | AA9: =I9*ReturnData!I20 -> 0 | ... AI9: =Q9*ReturnData!Q20 -> -0.00915 | AK9: =S9 -> 197507 | AL9: =SUM(T9:AI9) -> -0.06145 | AN9: 1 | AO9: =HighMomentumPortfolio!AL9-LowMomentumPortfolio!AL9 -> 0.0151875 | AP9: =AN9+AO9 -> 1.0151875
A10: =ReturnData!A21 -> 197508 | B10: =IF('Monthly Ranks'!B9>=9, 1/8,0) -> 0 | C10: =IF('Monthly Ranks'!C9>=9, 1/8,0) -> 0 | D10: =IF('Monthly Ranks'!D9>=9, 1/8,0) -> 0 | E10: =IF('Monthly Ranks'!E9>=9, 1/8,0) -> 0 | F10: =IF('Monthly Ranks'!F9>=9, 1/8,0) -> 0.125 | G10: =IF('Monthly Ranks'!G9>=9, 1/8,0) -> 0.125 | H10: =IF('Monthly Ranks'!H9>=9, 1/8,0) -> 0.125 | I10: =IF('Monthly Ranks'!I9>=9, 1/8,0) -> 0 | ... Q10: =IF('Monthly Ranks'!Q9>=9, 1/8,0) -> 0 | S10: =A10 -> 197508 | T10: =B10*ReturnData!B21 -> 0 | U10: =C10*ReturnData!C21 -> 0 | V10: =D10*ReturnData!D21 -> 0 | W10: =E10*ReturnData!E21 -> 0 | X10: =F10*ReturnData!F21 -> -0.0044375 | Y10: =G10*ReturnData!G21 -> 0.002475 | Z10: =H10*ReturnData!H21 -> -0.005225 | AA10: =I10*ReturnData!I21 -> 0 | ... AI10: =Q10*ReturnData!Q21 -> 0 | AK10: =S10 -> 197508 | AL10: =SUM(T10:AI10) -> -0.01275 | AN10: 1 | AO10: =HighMomentumPortfolio!AL10-LowMomentumPortfolio!AL10 -> -0.0186125 | AP10: =AN10+AO10 -> 0.9813875
A11: =ReturnData!A22 -> 197509 | B11: =IF('Monthly Ranks'!B10>=9, 1/8,0) -> 0 | C11: =IF('Monthly Ranks'!C10>=9, 1/8,0) -> 0 | D11: =IF('Monthly Ranks'!D10>=9, 1/8,0) -> 0 | E11: =IF('Monthly Ranks'!E10>=9, 1/8,0) -> 0 | F11: =IF('Monthly Ranks'!F10>=9, 1/8,0) -> 0.125 | G11: =IF('Monthly Ranks'!G10>=9, 1/8,0) -> 0.125 | H11: =IF('Monthly Ranks'!H10>=9, 1/8,0) -> 0.125 | I11: =IF('Monthly Ranks'!I10>=9, 1/8,0) -> 0 | ... Q11: =IF('Monthly Ranks'!Q10>=9, 1/8,0) -> 0.125 | S11: =A11 -> 197509 | T11: =B11*ReturnData!B22 -> 0 | U11: =C11*ReturnData!C22 -> 0 | V11: =D11*ReturnData!D22 -> 0 | W11: =E11*ReturnData!E22 -> 0 | X11: =F11*ReturnData!F22 -> -0.0052 | Y11: =G11*ReturnData!G22 -> -0.0106125 | Z11: =H11*ReturnData!H22 -> -0.0059875 | AA11: =I11*ReturnData!I22 -> 0 | ... AI11: =Q11*ReturnData!Q22 -> -0.0093875 | AK11: =S11 -> 197509 | AL11: =SUM(T11:AI11) -> -0.04595 | AN11: 1 | AO11: =HighMomentumPortfolio!AL11-LowMomentumPortfolio!AL11 -> 0.0180875 | AP11: =AN11+AO11 -> 1.0180875
A12: =ReturnData!A23 -> 197510 | B12: =IF('Monthly Ranks'!B11>=9, 1/8,0) -> 0 | C12: =IF('Monthly Ranks'!C11>=9, 1/8,0) -> 0 | D12: =IF('Monthly Ranks'!D11>=9, 1/8,0) -> 0 | E12: =IF('Monthly Ranks'!E11>=9, 1/8,0) -> 0 | F12: =IF('Monthly Ranks'!F11>=9, 1/8,0) -> 0.125 | G12: =IF('Monthly Ranks'!G11>=9, 1/8,0) -> 0 | H12: =IF('Monthly Ranks'!H11>=9, 1/8,0) -> 0.125 | I12: =IF('Monthly Ranks'!I11>=9, 1/8,0) -> 0 | ... Q12: =IF('Monthly Ranks'!Q11>=9, 1/8,0) -> 0.125 | S12: =A12 -> 197510 | T12: =B12*ReturnData!B23 -> 0 | U12: =C12*ReturnData!C23 -> 0 | V12: =D12*ReturnData!D23 -> 0 | W12: =E12*ReturnData!E23 -> 0 | X12: =F12*ReturnData!F23 -> 0.010975 | Y12: =G12*ReturnData!G23 -> 0 | Z12: =H12*ReturnData!H23 -> 0.01215 | AA12: =I12*ReturnData!I23 -> 0 | ... AI12: =Q12*ReturnData!Q23 -> 0.0062875 | AK12: =S12 -> 197510 | AL12: =SUM(T12:AI12) -> 0.0592875 | AN12: 1 | AO12: =HighMomentumPortfolio!AL12-LowMomentumPortfolio!AL12 -> -0.010225 | AP12: =AN12+AO12 -> 0.989775
A13: =ReturnData!A24 -> 197511 | B13: =IF('Monthly Ranks'!B12>=9, 1/8,0) -> 0 | C13: =IF('Monthly Ranks'!C12>=9, 1/8,0) -> 0.125 | D13: =IF('Monthly Ranks'!D12>=9, 1/8,0) -> 0.125 | E13: =IF('Monthly Ranks'!E12>=9, 1/8,0) -> 0 | F13: =IF('Monthly Ranks'!F12>=9, 1/8,0) -> 0.125 | G13: =IF('Monthly Ranks'!G12>=9, 1/8,0) -> 0.125 | H13: =IF('Monthly Ranks'!H12>=9, 1/8,0) -> 0.125 | I13: =IF('Monthly Ranks'!I12>=9, 1/8,0) -> 0 | ... Q13: =IF('Monthly Ranks'!Q12>=9, 1/8,0) -> 0.125 | S13: =A13 -> 197511 | T13: =B13*ReturnData!B24 -> 0 | U13: =C13*ReturnData!C24 -> -0.0018125 | V13: =D13*ReturnData!D24 -> -0.002475 | W13: =E13*ReturnData!E24 -> 0 | X13: =F13*ReturnData!F24 -> 0.0040125 | Y13: =G13*ReturnData!G24 -> 0.0025375 | Z13: =H13*ReturnData!H24 -> 0.0064125 | AA13: =I13*ReturnData!I24 -> 0 | ... AI13: =Q13*ReturnData!Q24 -> 0.0060375 | AK13: =S13 -> 197511 | AL13: =SUM(T13:AI13) -> 0.0235375 | AN13: 1 | AO13: =HighMomentumPortfolio!AL13-LowMomentumPortfolio!AL13 -> 0.010475 | AP13: =AN13+AO13 -> 1.010475
A14: =ReturnData!A25 -> 197512 | B14: =IF('Monthly Ranks'!B13>=9, 1/8,0) -> 0 | C14: =IF('Monthly Ranks'!C13>=9, 1/8,0) -> 0.125 | D14: =IF('Monthly Ranks'!D13>=9, 1/8,0) -> 0.125 | E14: =IF('Monthly Ranks'!E13>=9, 1/8,0) -> 0 | F14: =IF('Monthly Ranks'!F13>=9, 1/8,0) -> 0 | G14: =IF('Monthly Ranks'!G13>=9, 1/8,0) -> 0 | H14: =IF('Monthly Ranks'!H13>=9, 1/8,0) -> 0.125 | I14: =IF('Monthly Ranks'!I13>=9, 1/8,0) -> 0 | ... Q14: =IF('Monthly Ranks'!Q13>=9, 1/8,0) -> 0.125 | S14: =A14 -> 197512 | T14: =B14*ReturnData!B25 -> 0 | U14: =C14*ReturnData!C25 -> 0.00295 | V14: =D14*ReturnData!D25 -> 0.00035 | W14: =E14*ReturnData!E25 -> 0 | X14: =F14*ReturnData!F25 -> 0 | Y14: =G14*ReturnData!G25 -> 0 | Z14: =H14*ReturnData!H25 -> -0.0070875 | AA14: =I14*ReturnData!I25 -> 0 | ... AI14: =Q14*ReturnData!Q25 -> -0.000575 | AK14: =S14 -> 197512 | AL14: =SUM(T14:AI14) -> -0.0073 | AN14: 1 | AO14: =HighMomentumPortfolio!AL14-LowMomentumPortfolio!AL14 -> 0.001175 | AP14: =AN14+AO14 -> 1.001175
A15: =ReturnData!A26 -> 197601 | B15: =IF('Monthly Ranks'!B14>=9, 1/8,0) -> 0 | C15: =IF('Monthly Ranks'!C14>=9, 1/8,0) -> 0.125 | D15: =IF('Monthly Ranks'!D14>=9, 1/8,0) -> 0.125 | E15: =IF('Monthly Ranks'!E14>=9, 1/8,0) -> 0 | F15: =IF('Monthly Ranks'!F14>=9, 1/8,0) -> 0 | G15: =IF('Monthly Ranks'!G14>=9, 1/8,0) -> 0 | H15: =IF('Monthly Ranks'!H14>=9, 1/8,0) -> 0.125 | I15: =IF('Monthly Ranks'!I14>=9, 1/8,0) -> 0 | ... Q15: =IF('Monthly Ranks'!Q14>=9, 1/8,0) -> 0.125 | S15: =A15 -> 197601 | T15: =B15*ReturnData!B26 -> 0 | U15: =C15*ReturnData!C26 -> 0.0184 | V15: =D15*ReturnData!D26 -> 0.0096375 | W15: =E15*ReturnData!E26 -> 0 | X15: =F15*ReturnData!F26 -> 0 | Y15: =G15*ReturnData!G26 -> 0 | Z15: =H15*ReturnData!H26 -> 0.009 | AA15: =I15*ReturnData!I26 -> 0 | ... AI15: =Q15*ReturnData!Q26 -> 0.015275 | AK15: =S15 -> 197601 | AL15: =SUM(T15:AI15) -> 0.134575 | AN15: 1 | AO15: =HighMomentumPortfolio!AL15-LowMomentumPortfolio!AL15 -> 0.0150125 | AP15: =AN15+AO15 -> 1.0150125 | AR15: =PRODUCT(AP15:AP26) -> 0.9812333
A16: =ReturnData!A27 -> 197602 | B16: =IF('Monthly Ranks'!B15>=9, 1/8,0) -> 0 | C16: =IF('Monthly Ranks'!C15>=9, 1/8,0) -> 0.125 | D16: =IF('Monthly Ranks'!D15>=9, 1/8,0) -> 0.125 | E16: =IF('Monthly Ranks'!E15>=9, 1/8,0) -> 0 | F16: =IF('Monthly Ranks'!F15>=9, 1/8,0) -> 0 | G16: =IF('Monthly Ranks'!G15>=9, 1/8,0) -> 0 | H16: =IF('Monthly Ranks'!H15>=9, 1/8,0) -> 0.125 | I16: =IF('Monthly Ranks'!I15>=9, 1/8,0) -> 0.125 | ... Q16: =IF('Monthly Ranks'!Q15>=9, 1/8,0) -> 0.125 | S16: =A16 -> 197602 | T16: =B16*ReturnData!B27 -> 0 | U16: =C16*ReturnData!C27 -> 0.0026875 | V16: =D16*ReturnData!D27 -> -0.0040125 | W16: =E16*ReturnData!E27 -> 0 | X16: =F16*ReturnData!F27 -> 0 | Y16: =G16*ReturnData!G27 -> 0 | Z16: =H16*ReturnData!H27 -> -0.0073375 | AA16: =I16*ReturnData!I27 -> 0.00755 | ... AI16: =Q16*ReturnData!Q27 -> 0.002375 | AK16: =S16 -> 197602 | AL16: =SUM(T16:AI16) -> 0.007875 | AN16: 1 | AO16: =HighMomentumPortfolio!AL16-LowMomentumPortfolio!AL16 -> 0.0192875 | AP16: =AN16+AO16 -> 1.0192875
A17: =ReturnData!A28 -> 197603 | B17: =IF('Monthly Ranks'!B16>=9, 1/8,0) -> 0.125 | C17: =IF('Monthly Ranks'!C16>=9, 1/8,0) -> 0.125 | D17: =IF('Monthly Ranks'!D16>=9, 1/8,0) -> 0.125 | E17: =IF('Monthly Ranks'!E16>=9, 1/8,0) -> 0 | F17: =IF('Monthly Ranks'!F16>=9, 1/8,0) -> 0.125 | G17: =IF('Monthly Ranks'!G16>=9, 1/8,0) -> 0 | H17: =IF('Monthly Ranks'!H16>=9, 1/8,0) -> 0.125 | I17: =IF('Monthly Ranks'!I16>=9, 1/8,0) -> 0 | ... Q17: =IF('Monthly Ranks'!Q16>=9, 1/8,0) -> 0.125 | S17: =A17 -> 197603 | T17: =B17*ReturnData!B28 -> 0.0008125 | U17: =C17*ReturnData!C28 -> 0.0054875 | V17: =D17*ReturnData!D28 -> 0.0094375 | W17: =E17*ReturnData!E28 -> 0 | X17: =F17*ReturnData!F28 -> 0.002325 | Y17: =G17*ReturnData!G28 -> 0 | Z17: =H17*ReturnData!H28 -> 0.0072875 | AA17: =I17*ReturnData!I28 -> 0 | ... AI17: =Q17*ReturnData!Q28 -> 0.0040375 | AK17: =S17 -> 197603 | AL17: =SUM(T17:AI17) -> 0.0316875 | AN17: 1 | AO17: =HighMomentumPortfolio!AL17-LowMomentumPortfolio!AL17 -> -0.013275 | AP17: =AN17+AO17 -> 0.986725
A18: =ReturnData!A29 -> 197604 | B18: =IF('Monthly Ranks'!B17>=9, 1/8,0) -> 0.125 | C18: =IF('Monthly Ranks'!C17>=9, 1/8,0) -> 0.125 | D18: =IF('Monthly Ranks'!D17>=9, 1/8,0) -> 0.125 | E18: =IF('Monthly Ranks'!E17>=9, 1/8,0) -> 0 | F18: =IF('Monthly Ranks'!F17>=9, 1/8,0) -> 0.125 | G18: =IF('Monthly Ranks'!G17>=9, 1/8,0) -> 0 | H18: =IF('Monthly Ranks'!H17>=9, 1/8,0) -> 0.125 | I18: =IF('Monthly Ranks'!I17>=9, 1/8,0) -> 0 | ... Q18: =IF('Monthly Ranks'!Q17>=9, 1/8,0) -> 0.125 | S18: =A18 -> 197604 | T18: =B18*ReturnData!B29 -> -0.0016125 | U18: =C18*ReturnData!C29 -> 0.0035 | V18: =D18*ReturnData!D29 -> 0.00225 | W18: =E18*ReturnData!E29 -> 0 | X18: =F18*ReturnData!F29 -> -0.00615 | Y18: =G18*ReturnData!G29 -> 0 | Z18: =H18*ReturnData!H29 -> -0.0044875 | AA18: =I18*ReturnData!I29 -> 0 | ... AI18: =Q18*ReturnData!Q29 -> -0.003275 | AK18: =S18 -> 197604 | AL18: =SUM(T18:AI18) -> -0.01035 | AN18: 1 | AO18: =HighMomentumPortfolio!AL18-LowMomentumPortfolio!AL18 -> 0.0030125 | AP18: =AN18+AO18 -> 1.0030125
A19: =ReturnData!A30 -> 197605 | B19: =IF('Monthly Ranks'!B18>=9, 1/8,0) -> 0.125 | C19: =IF('Monthly Ranks'!C18>=9, 1/8,0) -> 0.125 | D19: =IF('Monthly Ranks'!D18>=9, 1/8,0) -> 0.125 | E19: =IF('Monthly Ranks'!E18>=9, 1/8,0) -> 0 | F19: =IF('Monthly Ranks'!F18>=9, 1/8,0) -> 0.125 | G19: =IF('Monthly Ranks'!G18>=9, 1/8,0) -> 0.125 | H19: =IF('Monthly Ranks'!H18>=9, 1/8,0) -> 0.125 | I19: =IF('Monthly Ranks'!I18>=9, 1/8,0) -> 0 | ... Q19: =IF('Monthly Ranks'!Q18>=9, 1/8,0) -> 0.125 | S19: =A19 -> 197605 | T19: =B19*ReturnData!B30 -> -0.0012 | U19: =C19*ReturnData!C30 -> 0.0032125 | V19: =D19*ReturnData!D30 -> 0.0077875 | W19: =E19*ReturnData!E30 -> 0 | X19: =F19*ReturnData!F30 -> -0.00395 | Y19: =G19*ReturnData!G30 -> -0.003375 | Z19: =H19*ReturnData!H30 -> -0.0029625 | AA19: =I19*ReturnData!I30 -> 0 | ... AI19: =Q19*ReturnData!Q30 -> -0.002675 | AK19: =S19 -> 197605 | AL19: =SUM(T19:AI19) -> -0.00265 | AN19: 1 | AO19: =HighMomentumPortfolio!AL19-LowMomentumPortfolio!AL19 -> -0.0199375 | AP19: =AN19+AO19 -> 0.9800625
A20: =ReturnData!A31 -> 197606 | B20: =IF('Monthly Ranks'!B19>=9, 1/8,0) -> 0.125 | C20: =IF('Monthly Ranks'!C19>=9, 1/8,0) -> 0.125 | D20: =IF('Monthly Ranks'!D19>=9, 1/8,0) -> 0.125 | E20: =IF('Monthly Ranks'!E19>=9, 1/8,0) -> 0 | F20: =IF('Monthly Ranks'!F19>=9, 1/8,0) -> 0.125 | G20: =IF('Monthly Ranks'!G19>=9, 1/8,0) -> 0 | H20: =IF('Monthly Ranks'!H19>=9, 1/8,0) -> 0.125 | I20: =IF('Monthly Ranks'!I19>=9, 1/8,0) -> 0 | ... Q20: =IF('Monthly Ranks'!Q19>=9, 1/8,0) -> 0.125 | S20: =A20 -> 197606 | T20: =B20*ReturnData!B31 -> 0.006825 | U20: =C20*ReturnData!C31 -> 0.0058 | V20: =D20*ReturnData!D31 -> 0.0061875 | W20: =E20*ReturnData!E31 -> 0 | X20: =F20*ReturnData!F31 -> 0.006525 | Y20: =G20*ReturnData!G31 -> 0 | Z20: =H20*ReturnData!H31 -> 0.0057625 | AA20: =I20*ReturnData!I31 -> 0 | ... AI20: =Q20*ReturnData!Q31 -> 0.00805 | AK20: =S20 -> 197606 | AL20: =SUM(T20:AI20) -> 0.0598375 | AN20: 1 | AO20: =HighMomentumPortfolio!AL20-LowMomentumPortfolio!AL20 -> -0.02985 | AP20: =AN20+AO20 -> 0.97015
A21: =ReturnData!A32 -> 197607 | B21: =IF('Monthly Ranks'!B20>=9, 1/8,0) -> 0.125 | C21: =IF('Monthly Ranks'!C20>=9, 1/8,0) -> 0.125 | D21: =IF('Monthly Ranks'!D20>=9, 1/8,0) -> 0 | E21: =IF('Monthly Ranks'!E20>=9, 1/8,0) -> 0 | F21: =IF('Monthly Ranks'!F20>=9, 1/8,0) -> 0.125 | G21: =IF('Monthly Ranks'!G20>=9, 1/8,0) -> 0 | H21: =IF('Monthly Ranks'!H20>=9, 1/8,0) -> 0.125 | I21: =IF('Monthly Ranks'!I20>=9, 1/8,0) -> 0 | ... Q21: =IF('Monthly Ranks'!Q20>=9, 1/8,0) -> 0.125 | S21: =A21 -> 197607 | T21: =B21*ReturnData!B32 -> 0.0022125 | U21: =C21*ReturnData!C32 -> -0.00475 | V21: =D21*ReturnData!D32 -> 0 | W21: =E21*ReturnData!E32 -> 0 | X21: =F21*ReturnData!F32 -> -0.0039625 | Y21: =G21*ReturnData!G32 -> 0 | Z21: =H21*ReturnData!H32 -> -0.0001375 | AA21: =I21*ReturnData!I32 -> 0 | ... AI21: =Q21*ReturnData!Q32 -> 0.00145 | AK21: =S21 -> 197607 | AL21: =SUM(T21:AI21) -> -0.0073625 | AN21: 1 | AO21: =HighMomentumPortfolio!AL21-LowMomentumPortfolio!AL21 -> -0.0085 | AP21: =AN21+AO21 -> 0.9915
A22: =ReturnData!A33 -> 197608 | B22: =IF('Monthly Ranks'!B21>=9, 1/8,0) -> 0.125 | C22: =IF('Monthly Ranks'!C21>=9, 1/8,0) -> 0.125 | D22: =IF('Monthly Ranks'!D21>=9, 1/8,0) -> 0 | E22: =IF('Monthly Ranks'!E21>=9, 1/8,0) -> 0 | F22: =IF('Monthly Ranks'!F21>=9, 1/8,0) -> 0.125 | G22: =IF('Monthly Ranks'!G21>=9, 1/8,0) -> 0.125 | H22: =IF('Monthly Ranks'!H21>=9, 1/8,0) -> 0.125 | I22: =IF('Monthly Ranks'!I21>=9, 1/8,0) -> 0 | ... Q22: =IF('Monthly Ranks'!Q21>=9, 1/8,0) -> 0.125 | S22: =A22 -> 197608 | T22: =B22*ReturnData!B33 -> -0.0005625 | U22: =C22*ReturnData!C33 -> -0.0047375 | V22: =D22*ReturnData!D33 -> 0 | W22: =E22*ReturnData!E33 -> 0 | X22: =F22*ReturnData!F33 -> -0.0014625 | Y22: =G22*ReturnData!G33 -> -0.0041875 | Z22: =H22*ReturnData!H33 -> 0.002275 | AA22: =I22*ReturnData!I33 -> 0 | ... AI22: =Q22*ReturnData!Q33 -> -0.0001875 | AK22: =S22 -> 197608 | AL22: =SUM(T22:AI22) -> -0.000475 | AN22: 1 | AO22: =HighMomentumPortfolio!AL22-LowMomentumPortfolio!AL22 -> -0.0174625 | AP22: =AN22+AO22 -> 0.9825375
A23: =ReturnData!A34 -> 197609 | B23: =IF('Monthly Ranks'!B22>=9, 1/8,0) -> 0.125 | C23: =IF('Monthly Ranks'!C22>=9, 1/8,0) -> 0.125 | D23: =IF('Monthly Ranks'!D22>=9, 1/8,0) -> 0.125 | E23: =IF('Monthly Ranks'!E22>=9, 1/8,0) -> 0 | F23: =IF('Monthly Ranks'!F22>=9, 1/8,0) -> 0.125 | G23: =IF('Monthly Ranks'!G22>=9, 1/8,0) -> 0.125 | H23: =IF('Monthly Ranks'!H22>=9, 1/8,0) -> 0.125 | I23: =IF('Monthly Ranks'!I22>=9, 1/8,0) -> 0 | ... Q23: =IF('Monthly Ranks'!Q22>=9, 1/8,0) -> 0.125 | S23: =A23 -> 197609 | T23: =B23*ReturnData!B34 -> 0.0002 | U23: =C23*ReturnData!C34 -> 0.0032125 | V23: =D23*ReturnData!D34 -> 0.0075375 | W23: =E23*ReturnData!E34 -> 0 | X23: =F23*ReturnData!F34 -> -0.000925 | Y23: =G23*ReturnData!G34 -> 0.0004 | Z23: =H23*ReturnData!H34 -> 0.0040375 | AA23: =I23*ReturnData!I34 -> 0 | ... AI23: =Q23*ReturnData!Q34 -> 0.00065 | AK23: =S23 -> 197609 | AL23: =SUM(T23:AI23) -> 0.015575 | AN23: 1 | AO23: =HighMomentumPortfolio!AL23-LowMomentumPortfolio!AL23 -> 0.0119125 | AP23: =AN23+AO23 -> 1.0119125
A24: =ReturnData!A35 -> 197610 | B24: =IF('Monthly Ranks'!B23>=9, 1/8,0) -> 0.125 | C24: =IF('Monthly Ranks'!C23>=9, 1/8,0) -> 0.125 | D24: =IF('Monthly Ranks'!D23>=9, 1/8,0) -> 0.125 | E24: =IF('Monthly Ranks'!E23>=9, 1/8,0) -> 0 | F24: =IF('Monthly Ranks'!F23>=9, 1/8,0) -> 0.125 | G24: =IF('Monthly Ranks'!G23>=9, 1/8,0) -> 0.125 | H24: =IF('Monthly Ranks'!H23>=9, 1/8,0) -> 0.125 | I24: =IF('Monthly Ranks'!I23>=9, 1/8,0) -> 0 | ... Q24: =IF('Monthly Ranks'!Q23>=9, 1/8,0) -> 0 | S24: =A24 -> 197610 | T24: =B24*ReturnData!B35 -> -0.00285 | U24: =C24*ReturnData!C35 -> -0.0029875 | V24: =D24*ReturnData!D35 -> -0.0029375 | W24: =E24*ReturnData!E35 -> 0 | X24: =F24*ReturnData!F35 -> -0.0035875 | Y24: =G24*ReturnData!G35 -> -0.0030125 | Z24: =H24*ReturnData!H35 -> -0.003325 | AA24: =I24*ReturnData!I35 -> 0 | ... AI24: =Q24*ReturnData!Q35 -> 0 | AK24: =S24 -> 197610 | AL24: =SUM(T24:AI24) -> -0.024625 | AN24: 1 | AO24: =HighMomentumPortfolio!AL24-LowMomentumPortfolio!AL24 -> 0.0043 | AP24: =AN24+AO24 -> 1.0043
A25: =ReturnData!A36 -> 197611 | B25: =IF('Monthly Ranks'!B24>=9, 1/8,0) -> 0.125 | C25: =IF('Monthly Ranks'!C24>=9, 1/8,0) -> 0 | D25: =IF('Monthly Ranks'!D24>=9, 1/8,0) -> 0 | E25: =IF('Monthly Ranks'!E24>=9, 1/8,0) -> 0.125 | F25: =IF('Monthly Ranks'!F24>=9, 1/8,0) -> 0.125 | G25: =IF('Monthly Ranks'!G24>=9, 1/8,0) -> 0.125 | H25: =IF('Monthly Ranks'!H24>=9, 1/8,0) -> 0.125 | I25: =IF('Monthly Ranks'!I24>=9, 1/8,0) -> 0 | ... Q25: =IF('Monthly Ranks'!Q24>=9, 1/8,0) -> 0.125 | S25: =A25 -> 197611 | T25: =B25*ReturnData!B36 -> 0.0004625 | U25: =C25*ReturnData!C36 -> 0 | V25: =D25*ReturnData!D36 -> 0 | W25: =E25*ReturnData!E36 -> 0.0086375 | X25: =F25*ReturnData!F36 -> -0.0018125 | Y25: =G25*ReturnData!G36 -> -0.0064125 | Z25: =H25*ReturnData!H36 -> -0.0077875 | AA25: =I25*ReturnData!I36 -> 0 | ... AI25: =Q25*ReturnData!Q36 -> 0.0021375 | AK25: =S25 -> 197611 | AL25: =SUM(T25:AI25) -> 0.005475 | AN25: 1 | AO25: =HighMomentumPortfolio!AL25-LowMomentumPortfolio!AL25 -> 0.0086875 | AP25: =AN25+AO25 -> 1.0086875
A26: =ReturnData!A37 -> 197612 | B26: =IF('Monthly Ranks'!B25>=9, 1/8,0) -> 0.125 | C26: =IF('Monthly Ranks'!C25>=9, 1/8,0) -> 0 | D26: =IF('Monthly Ranks'!D25>=9, 1/8,0) -> 0 | E26: =IF('Monthly Ranks'!E25>=9, 1/8,0) -> 0.125 | F26: =IF('Monthly Ranks'!F25>=9, 1/8,0) -> 0.125 | G26: =IF('Monthly Ranks'!G25>=9, 1/8,0) -> 0.125 | H26: =IF('Monthly Ranks'!H25>=9, 1/8,0) -> 0.125 | I26: =IF('Monthly Ranks'!I25>=9, 1/8,0) -> 0 | ... Q26: =IF('Monthly Ranks'!Q25>=9, 1/8,0) -> 0.125 | S26: =A26 -> 197612 | T26: =B26*ReturnData!B37 -> 0.0057625 | U26: =C26*ReturnData!C37 -> 0 | V26: =D26*ReturnData!D37 -> 0 | W26: =E26*ReturnData!E37 -> 0.0079875 | X26: =F26*ReturnData!F37 -> 0.0059125 | Y26: =G26*ReturnData!G37 -> 0.012725 | Z26: =H26*ReturnData!H37 -> 0.0066 | AA26: =I26*ReturnData!I37 -> 0 | ... AI26: =Q26*ReturnData!Q37 -> 0.0111625 | AK26: =S26 -> 197612 | AL26: =SUM(T26:AI26) -> 0.0601875 | AN26: 1 | AO26: =HighMomentumPortfolio!AL26-LowMomentumPortfolio!AL26 -> 0.0092625 | AP26: =AN26+AO26 -> 1.0092625
A27: =ReturnData!A38 -> 197701 | B27: =IF('Monthly Ranks'!B26>=9, 1/8,0) -> 0.125 | C27: =IF('Monthly Ranks'!C26>=9, 1/8,0) -> 0 | D27: =IF('Monthly Ranks'!D26>=9, 1/8,0) -> 0 | E27: =IF('Monthly Ranks'!E26>=9, 1/8,0) -> 0.125 | F27: =IF('Monthly Ranks'!F26>=9, 1/8,0) -> 0.125 | G27: =IF('Monthly Ranks'!G26>=9, 1/8,0) -> 0.125 | H27: =IF('Monthly Ranks'!H26>=9, 1/8,0) -> 0.125 | I27: =IF('Monthly Ranks'!I26>=9, 1/8,0) -> 0 | ... Q27: =IF('Monthly Ranks'!Q26>=9, 1/8,0) -> 0 | S27: =A27 -> 197701 | T27: =B27*ReturnData!B38 -> -0.006275 | U27: =C27*ReturnData!C38 -> 0 | V27: =D27*ReturnData!D38 -> 0 | W27: =E27*ReturnData!E38 -> -0.0008125 | X27: =F27*ReturnData!F38 -> -0.009975 | Y27: =G27*ReturnData!G38 -> -0.0071625 | Z27: =H27*ReturnData!H38 -> -0.0100875 | AA27: =I27*ReturnData!I38 -> 0 | ... AI27: =Q27*ReturnData!Q38 -> 0 | AK27: =S27 -> 197701 | AL27: =SUM(T27:AI27) -> -0.04815 | AN27: 1 | AO27: =HighMomentumPortfolio!AL27-LowMomentumPortfolio!AL27 -> 0.022325 | AP27: =AN27+AO27 -> 1.022325 | AR27: =PRODUCT(AP27:AP38) -> 1.1031385
A28: =ReturnData!A39 -> 197702 | B28: =IF('Monthly Ranks'!B27>=9, 1/8,0) -> 0.125 | C28: =IF('Monthly Ranks'!C27>=9, 1/8,0) -> 0 | D28: =IF('Monthly Ranks'!D27>=9, 1/8,0) -> 0 | E28: =IF('Monthly Ranks'!E27>=9, 1/8,0) -> 0.125 | F28: =IF('Monthly Ranks'!F27>=9, 1/8,0) -> 0.125 | G28: =IF('Monthly Ranks'!G27>=9, 1/8,0) -> 0.125 | H28: =IF('Monthly Ranks'!H27>=9, 1/8,0) -> 0.125 | I28: =IF('Monthly Ranks'!I27>=9, 1/8,0) -> 0 | ... Q28: =IF('Monthly Ranks'!Q27>=9, 1/8,0) -> 0 | S28: =A28 -> 197702 | T28: =B28*ReturnData!B39 -> -0.0008125 | U28: =C28*ReturnData!C39 -> 0 | V28: =D28*ReturnData!D39 -> 0 | W28: =E28*ReturnData!E39 -> -0.0057125 | X28: =F28*ReturnData!F39 -> -0.003225 | Y28: =G28*ReturnData!G39 -> -0.00095 | Z28: =H28*ReturnData!H39 -> -0.00045 | AA28: =I28*ReturnData!I39 -> 0 | ... AI28: =Q28*ReturnData!Q39 -> 0 | AK28: =S28 -> 197702 | AL28: =SUM(T28:AI28) -> -0.014225 | AN28: 1 | AO28: =HighMomentumPortfolio!AL28-LowMomentumPortfolio!AL28 -> -0.0060375 | AP28: =AN28+AO28 -> 0.9939625
A29: =ReturnData!A40 -> 197703 | B29: =IF('Monthly Ranks'!B28>=9, 1/8,0) -> 0.125 | C29: =IF('Monthly Ranks'!C28>=9, 1/8,0) -> 0 | D29: =IF('Monthly Ranks'!D28>=9, 1/8,0) -> 0 | E29: =IF('Monthly Ranks'!E28>=9, 1/8,0) -> 0.125 | F29: =IF('Monthly Ranks'!F28>=9, 1/8,0) -> 0.125 | G29: =IF('Monthly Ranks'!G28>=9, 1/8,0) -> 0.125 | H29: =IF('Monthly Ranks'!H28>=9, 1/8,0) -> 0.125 | I29: =IF('Monthly Ranks'!I28>=9, 1/8,0) -> 0 | ... Q29: =IF('Monthly Ranks'!Q28>=9, 1/8,0) -> 0 | S29: =A29 -> 197703 | T29: =B29*ReturnData!B40 -> -0.0014875 | U29: =C29*ReturnData!C40 -> 0 | V29: =D29*ReturnData!D40 -> 0 | W29: =E29*ReturnData!E40 -> -0.001225 | X29: =F29*ReturnData!F40 -> -0.0048375 | Y29: =G29*ReturnData!G40 -> -0.0005125 | Z29: =H29*ReturnData!H40 -> -0.0028 | AA29: =I29*ReturnData!I40 -> 0 | ... AI29: =Q29*ReturnData!Q40 -> 0 | AK29: =S29 -> 197703 | AL29: =SUM(T29:AI29) -> -0.0131125 | AN29: 1 | AO29: =HighMomentumPortfolio!AL29-LowMomentumPortfolio!AL29 -> 0.009275 | AP29: =AN29+AO29 -> 1.009275
A30: =ReturnData!A41 -> 197704 | B30: =IF('Monthly Ranks'!B29>=9, 1/8,0) -> 0.125 | C30: =IF('Monthly Ranks'!C29>=9, 1/8,0) -> 0 | D30: =IF('Monthly Ranks'!D29>=9, 1/8,0) -> 0 | E30: =IF('Monthly Ranks'!E29>=9, 1/8,0) -> 0.125 | F30: =IF('Monthly Ranks'!F29>=9, 1/8,0) -> 0.125 | G30: =IF('Monthly Ranks'!G29>=9, 1/8,0) -> 0.125 | H30: =IF('Monthly Ranks'!H29>=9, 1/8,0) -> 0.125 | I30: =IF('Monthly Ranks'!I29>=9, 1/8,0) -> 0 | ... Q30: =IF('Monthly Ranks'!Q29>=9, 1/8,0) -> 0 | S30: =A30 -> 197704 | T30: =B30*ReturnData!B41 -> -0.00025 | U30: =C30*ReturnData!C41 -> 0 | V30: =D30*ReturnData!D41 -> 0 | W30: =E30*ReturnData!E41 -> 0.0028875 | X30: =F30*ReturnData!F41 -> -0.0013125 | Y30: =G30*ReturnData!G41 -> -0.000675 | Z30: =H30*ReturnData!H41 -> -0.003675 | AA30: =I30*ReturnData!I41 -> 0 | ... AI30: =Q30*ReturnData!Q41 -> 0 | AK30: =S30 -> 197704 | AL30: =SUM(T30:AI30) -> -0.0089 | AN30: 1 | AO30: =HighMomentumPortfolio!AL30-LowMomentumPortfolio!AL30 -> 0.0329625 | AP30: =AN30+AO30 -> 1.0329625
